Workbook

Sheet results.csv
A1: Test ID | B1: Solver | C1: Variables | D1: Clause Size | E1: Clauses | F1: Solving Time (s) | G1: Solutions Found
A2: 1 | B2: BlastSolver | C2: 10 | D2: 10 | E2: 100 | F2: 0.077568531 | G2: 926
A3: 1 | B3: PySATSolver | C3: 10 | D3: 10 | E3: 100 | F3: 0.0040016174 | G3: 926
A4: 1 | B4: SymPySolver | C4: 10 | D4: 10 | E4: 100 | F4: 0.058305502 | G4: 926
A5: 1 | B5: PyEDASolver | C5: 10 | D5: 10 | E5: 100 | F5: 0.017934084 | G5: 926
A6: 2 | B6: BlastSolver | C6: 10 | D6: 10 | E6: 100 | F6: 0.076648474 | G6: 931
A7: 2 | B7: PySATSolver | C7: 10 | D7: 10 | E7: 100 | F7: 0.0050022602 | G7: 931
A8: 2 | B8: SymPySolver | C8: 10 | D8: 10 | E8: 100 | F8: 0.034038305 | G8: 931
A9: 2 | B9: PyEDASolver | C9: 10 | D9: 10 | E9: 100 | F9: 0.018010616 | G9: 931
A10: 3 | B10: BlastSolver | C10: 10 | D10: 10 | E10: 100 | F10: 0.091692686 | G10: 929
A11: 3 | B11: PySATSolver | C11: 10 | D11: 10 | E11: 100 | F11: 0.004442215 | G11: 929
A12: 3 | B12: SymPySolver | C12: 10 | D12: 10 | E12: 100 | F12: 0.033270121 | G12: 929
A13: 3 | B13: PyEDASolver | C13: 10 | D13: 10 | E13: 100 | F13: 0.017066479 | G13: 929
... A286: 72 | B286: BlastSolver | C286: 17 | D286: 17 | E286: 170 | F286: 0.44591761 | G286: 130902
A287: 72 | B287: PySATSolver | C287: 17 | D287: 17 | E287: 170
A288: 72 | B288: SymPySolver | C288: 17 | D288: 17 | E288: 170 | F288: 2.4817221 | G288: 130902
A289: 72 | B289: PyEDASolver | C289: 17 | D289: 17 | E289: 170
A290: 73 | B290: BlastSolver | C290: 17 | D290: 17 | E290: 170 | F290: 0.52840233 | G290: 130902
A291: 73 | B291: PySATSolver | C291: 17 | D291: 17 | E291: 170
A292: 73 | B292: SymPySolver | C292: 17 | D292: 17 | E292: 170 | F292: 1.7195525 | G292: 130902
A293: 73 | B293: PyEDASolver | C293: 17 | D293: 17 | E293: 170
A294: 74 | B294: BlastSolver | C294: 17 | D294: 17 | E294: 170 | F294: 0.46829557 | G294: 130902
A295: 74 | B295: PySATSolver | C295: 17 | D295: 17 | E295: 170
A296: 74 | B296: SymPySolver | C296: 17 | D296: 17 | E296: 170 | F296: 2.3006468 | G296: 130902
A297: 74 | B297: PyEDASolver | C297: 17 | D297: 17 | E297: 170
A298: 75 | B298: BlastSolver | C298: 17 | D298: 17 | E298: 170 | F298: 0.52856493 | G298: 130902
A299: 75 | B299: PySATSolver | C299: 17 | D299: 17 | E299: 170
A300: 75 | B300: SymPySolver | C300: 17 | D300: 17 | E300: 170 | F300: 2.006995 | G300: 130902
A301: 75 | B301: PyEDASolver | C301: 17 | D301: 17 | E301: 170
A302: 76 | B302: BlastSolver | C302: 17 | D302: 17 | E302: 170 | F302: 0.57598209 | G302: 130902
A303: 76 | B303: PySATSolver | C303: 17 | D303: 17 | E303: 170
A304: 76 | B304: SymPySolver | C304: 17 | D304: 17 | E304: 170 | F304: 1.9853096 | G304: 130902
A305: 76 | B305: PyEDASolver | C305: 17 | D305: 17 | E305: 170
A306: 77 | B306: BlastSolver | C306: 17 | D306: 17 | E306: 170 | F306: 0.53689408 | G306: 130902
A307: 77 | B307: PySATSolver | C307: 17 | D307: 17 | E307: 170
A308: 77 | B308: SymPySolver | C308: 17 | D308: 17 | E308: 170 | F308: 1.8526893 | G308: 130902
A309: 77 | B309: PyEDASolver | C309: 17 | D309: 17 | E309: 170
A310: 78 | B310: BlastSolver | C310: 17 | D310: 17 | E310: 170 | F310: 0.48148251 | G310: 130902
A311: 78 | B311: PySATSolver | C311: 17 | D311: 17 | E311: 170
A312: 78 | B312: SymPySolver | C312: 17 | D312: 17 | E312: 170 | F312: 1.9415803 | G312: 130902
...

Sheet data
A1: Średnia z Solving Time (s) | B1: Solver
A2: Variables | B2: BlastSolver | C2: PyEDASolver | D2: PySATSolver | E2: SymPySolver
A3: 10 | B3: 0.07988534 | C3: 0.01918478 | D3: 0.004645443 | E3: 0.036801028
A4: 11 | B4: 0.10427518 | C4: 0.030219364 | D4: 0.013480997 | E4: 0.052598834
A5: 12 | B5: 0.13174388 | C5: 0.060512686 | D5: 0.041633749 | E5: 0.085124612
A6: 13 | B6: 0.17100742 | C6: 0.14001751 | D6: 0.16800604 | E6: 0.1507103
A7: 14 | B7: 0.21624856 | C7: 0.438835 | D7: 0.61299512 | E7: 0.25129189
A8: 15 | B8: 0.29573443 | C8: 1.5462017 | D8: 2.4776979 | E8: 0.5208369
A9: 16 | B9: 0.3799135 | C9: 7.3152618 | D9: 9.140943 | E9: 1.0320681
A10: 17 | B10: 0.49388051 | C10: 33.217245 | D10: 35.532829 | E10: 2.0860848
A11: 18 | B11: 0.66276832 | E11: 4.2313143
A12: 19 | B12: 1.0391191 | E12: 10.006088
A13: 20 | B13: 1.7509331 | E13: 18.86437
A14: 21 | B14: 3.2379926
A15: 22 | B15: 5.9158664
A16: 23 | B16: 13.136506
A17: 24 | B17: 32.647771
A18: 25

Sheet data_chart
A1: Liczba zmiennych | B1: BlastSolver | C1: PyEDASolver | D1: PySATSolver | E1: SymPySolver | F1: =data!F2 -> 0 | G1: =data!G2 -> 0 | H1: =data!H2 -> 0 | I1: =data!I2 -> 0 | J1: =data!J2 -> 0 | K1: =data!K2 -> 0 | L1: =data!L2 -> 0 | M1: =data!M2 -> 0 | ... XFD1: =data!XFD2 -> 0
A2: =data!A3 -> 10 | B2: =IF(data!B3>0,data!B3,"") -> 0.07988534 | C2: =IF(data!C3>0,data!C3,"") -> 0.01918478 | D2: =IF(data!D3>0,data!D3,"") -> 0.004645443 | E2: =IF(data!E3>0,data!E3,"") -> 0.036801028
A3: =data!A4 -> 11 | B3: =IF(data!B4>0,data!B4,"") -> 0.10427518 | C3: =IF(data!C4>0,data!C4,"") -> 0.030219364 | D3: =IF(data!D4>0,data!D4,"") -> 0.013480997 | E3: =IF(data!E4>0,data!E4,"") -> 0.052598834
A4: =data!A5 -> 12 | B4: =IF(data!B5>0,data!B5,"") -> 0.13174388 | C4: =IF(data!C5>0,data!C5,"") -> 0.060512686 | D4: =IF(data!D5>0,data!D5,"") -> 0.041633749 | E4: =IF(data!E5>0,data!E5,"") -> 0.085124612
A5: =data!A6 -> 13 | B5: =IF(data!B6>0,data!B6,"") -> 0.17100742 | C5: =IF(data!C6>0,data!C6,"") -> 0.14001751 | D5: =IF(data!D6>0,data!D6,"") -> 0.16800604 | E5: =IF(data!E6>0,data!E6,"") -> 0.1507103
A6: =data!A7 -> 14 | B6: =IF(data!B7>0,data!B7,"") -> 0.21624856 | C6: =IF(data!C7>0,data!C7,"") -> 0.438835 | D6: =IF(data!D7>0,data!D7,"") -> 0.61299512 | E6: =IF(data!E7>0,data!E7,"") -> 0.25129189
A7: =data!A8 -> 15 | B7: =IF(data!B8>0,data!B8,"") -> 0.29573443 | C7: =IF(data!C8>0,data!C8,"") -> 1.5462017 | D7: =IF(data!D8>0,data!D8,"") -> 2.4776979 | E7: =IF(data!E8>0,data!E8,"") -> 0.5208369
A8: =data!A9 -> 16 | B8: =IF(data!B9>0,data!B9,"") -> 0.3799135 | C8: =IF(data!C9>0,data!C9,"") -> 7.3152618 | D8: =IF(data!D9>0,data!D9,"") -> 9.140943 | E8: =IF(data!E9>0,data!E9,"") -> 1.0320681
A9: =data!A10 -> 17 | B9: =IF(data!B10>0,data!B10,"") -> 0.49388051 | C9: =IF(data!C10>0,data!C10,"") -> 33.217245 | D9: =IF(data!D10>0,data!D10,"") -> 35.532829 | E9: =IF(data!E10>0,data!E10,"") -> 2.0860848
A10: =data!A11 -> 18 | B10: =IF(data!B11>0,data!B11,"") -> 0.66276832 | E10: =IF(data!E11>0,data!E11,"") -> 4.2313143
A11: =data!A12 -> 19 | B11: =IF(data!B12>0,data!B12,"") -> 1.0391191 | E11: =IF(data!E12>0,data!E12,"") -> 10.006088
A12: =data!A13 -> 20 | B12: =IF(data!B13>0,data!B13,"") -> 1.7509331 | E12: =IF(data!E13>0,data!E13,"") -> 18.86437
A13: =data!A14 -> 21 | B13: =IF(data!B14>0,data!B14,"") -> 3.2379926
A14: =data!A15 -> 22 | B14: =IF(data!B15>0,data!B15,"") -> 5.9158664
A15: =data!A16 -> 23 | B15: =IF(data!B16>0,data!B16,"") -> 13.136506
A16: =data!A17 -> 24 | B16: =IF(data!B17>0,data!B17,"") -> 32.647771
